[2025-04-19T11:33:01.524+0000] {taskinstance.py:1956} INFO - Dependencies all met for dep_context=non-requeueable deps ti=<TaskInstance: ingest_bronze_csv_to_snowflake.check_azure_connection manual__2025-04-19T11:32:58.133423+00:00 [queued]>
[2025-04-19T11:33:01.551+0000] {taskinstance.py:1956} INFO - Dependencies all met for dep_context=requeueable deps ti=<TaskInstance: ingest_bronze_csv_to_snowflake.check_azure_connection manual__2025-04-19T11:32:58.133423+00:00 [queued]>
[2025-04-19T11:33:01.553+0000] {taskinstance.py:2170} INFO - Starting attempt 1 of 1
[2025-04-19T11:33:01.590+0000] {taskinstance.py:2191} INFO - Executing <Task(PythonOperator): check_azure_connection> on 2025-04-19 11:32:58.133423+00:00
[2025-04-19T11:33:01.608+0000] {standard_task_runner.py:60} INFO - Started process 326 to run task
[2025-04-19T11:33:01.620+0000] {standard_task_runner.py:87} INFO - Running: ['***', 'tasks', 'run', 'ingest_bronze_csv_to_snowflake', 'check_azure_connection', 'manual__2025-04-19T11:32:58.133423+00:00', '--job-id', '4', '--raw', '--subdir', 'DAGS_FOLDER/ingest_bronze_dag.py', '--cfg-path', '/tmp/tmpy_5wp45h']
[2025-04-19T11:33:01.646+0000] {standard_task_runner.py:88} INFO - Job 4: Subtask check_azure_connection
[2025-04-19T11:33:01.902+0000] {task_command.py:423} INFO - Running <TaskInstance: ingest_bronze_csv_to_snowflake.check_azure_connection manual__2025-04-19T11:32:58.133423+00:00 [running]> on host 66ec6d74a776
[2025-04-19T11:33:02.192+0000] {taskinstance.py:2480} INFO - Exporting env vars: AIRFLOW_CTX_DAG_OWNER='***' AIRFLOW_CTX_DAG_ID='ingest_bronze_csv_to_snowflake' AIRFLOW_CTX_TASK_ID='check_azure_connection' AIRFLOW_CTX_EXECUTION_DATE='2025-04-19T11:32:58.133423+00:00' AIRFLOW_CTX_TRY_NUMBER='1' AIRFLOW_CTX_DAG_RUN_ID='manual__2025-04-19T11:32:58.133423+00:00'
[2025-04-19T11:33:02.200+0000] {taskinstance.py:2698} ERROR - Task failed with exception
Traceback (most recent call last):
  File "/home/airflow/.local/lib/python3.10/site-packages/airflow/models/taskinstance.py", line 433, in _execute_task
    result = execute_callable(context=context, **execute_callable_kwargs)
  File "/home/airflow/.local/lib/python3.10/site-packages/airflow/operators/python.py", line 199, in execute
    return_value = self.execute_callable()
  File "/home/airflow/.local/lib/python3.10/site-packages/airflow/operators/python.py", line 216, in execute_callable
    return self.python_callable(*self.op_args, **self.op_kwargs)
  File "/opt/airflow/dags/ingest_bronze_dag.py", line 39, in check_azure_connection
    fs = AzureBlobFileSystem(account_name=BLOB_STORAGE_ACCOUNT, sas_token=BLOB_STORAGE_SAS)
NameError: name 'BLOB_STORAGE_SAS' is not defined. Did you mean: 'BLOB_STORAGE_SAS_TOKEN'?
[2025-04-19T11:33:02.273+0000] {taskinstance.py:1138} INFO - Marking task as FAILED. dag_id=ingest_bronze_csv_to_snowflake, task_id=check_azure_connection, execution_date=20250419T113258, start_date=20250419T113301, end_date=20250419T113302
[2025-04-19T11:33:02.323+0000] {standard_task_runner.py:107} ERROR - Failed to execute job 4 for task check_azure_connection (name 'BLOB_STORAGE_SAS' is not defined; 326)
[2025-04-19T11:33:02.389+0000] {local_task_job_runner.py:234} INFO - Task exited with return code 1
[2025-04-19T11:33:02.460+0000] {taskinstance.py:3280} INFO - 0 downstream tasks scheduled from follow-on schedule check
